<?xml version="1.0"?>
<robot xmlns:xacro="http://www.ros.org/wiki/xacro">

    <!-- Mathematical Constants -->
    <xacro:property name="PI" value="3.1415926535897931" />

    <!-- Macro for da Vinci Si PSM Base -->
    <xacro:macro name="psm_base" params="prefix parent_link xyz:='0.0 0.0 0.0' rpy:='0.0 0.0 0.0'">

        <!-- Link 0: -->
        <link name="${prefix}_link_0">
            <inertial>
                <origin xyz="-0.080771 2.1131E-08 1.8613E-07" rpy="0 0 0" />
                <mass value="1.5188" />
                <inertia ixx="0.002395" ixy="-2.6476E-18" ixz="-1.3484E-18" iyy="0.0040794" iyz="4.2598E-10" izz="0.0043778" />
            </inertial>
            <visual>
                <origin xyz="0 0 0" rpy="0 0 0" />
                <geometry>
                    <mesh filename="package://psm_description/meshes/Si/link_0.stl" />
                </geometry>
                <material name="Lavender">
                    <color rgba="0.79216 0.81961 0.93333 1" />
                </material>
            </visual>
            <collision>
                <origin xyz="0 0 0" rpy="0 0 0" />
                <geometry>
                    <mesh filename="package://psm_description/meshes/Si/link_0.stl" />
                </geometry>
            </collision>
        </link>

        <!-- Link 1: -->
        <link name="${prefix}_link_1">
            <inertial>
                <origin xyz="0.1461 0.090363 -0.024957" rpy="0 0 0" />
                <mass value="1.7571" />
                <inertia ixx="0.0049404" ixy="-0.0035267" ixz="0.0045945" iyy="0.019686" iyz="0.00070407" izz="0.020795" />
            </inertial>
            <visual>
                <origin xyz="0 0 0" rpy="0 0 0" />
                <geometry>
                    <mesh filename="package://psm_description/meshes/Si/link_1.stl" />
                </geometry>
                <material name="Lavender"/>
            </visual>
            <collision>
                <origin xyz="0 0 0" rpy="0 0 0" />
                <geometry>
                    <mesh filename="package://psm_description/meshes/Si/link_1.stl" />
                </geometry>
            </collision>
        </link>

        <!-- Link 2: -->
        <link name="${prefix}_link_2">
            <inertial>
                <origin xyz="0.083895 -0.00073113 -0.028998" rpy="0.0 0.0 0.0" />
                <mass value="4.017" />
                <inertia ixx="0.012797" ixy="-0.0002464" ixz="0.0011164" iyy="0.026307" iyz="8.5164E-05" izz="0.025616" />
            </inertial>
            <visual>
                <origin xyz="0 0 0" rpy="0 0 0" />
                <geometry>
                    <mesh filename="package://psm_description/meshes/Si/link_2.stl" />
                </geometry>
                <material name="Lavender"/>
            </visual>
            <collision>
                <origin xyz="0 0 0" rpy="0 0 0" />
                <geometry>
                    <mesh filename="package://psm_description/meshes/Si/link_2.stl" />
                </geometry>
            </collision>
        </link>

        <!-- Link 3: -->
        <link name="${prefix}_link_3">
            <inertial>
                <origin xyz="0.11824 1.9336E-19 0.12932" rpy="0 0 0" />
                <mass value="2.1982" />
                <inertia ixx="0.0076428" ixy="-2.8207E-19" ixz="-0.0074855" iyy="0.032839" iyz="-1.4256E-19" izz="0.026585" />
            </inertial>
            <visual>
                <origin xyz="0 0 0" rpy="0 0 0" />
                <geometry>
                    <mesh filename="package://psm_description/meshes/Si/link_3.stl" />
                </geometry>
                <material name="Lavender"/>
            </visual>
            <collision>
                <origin xyz="0 0 0" rpy="0 0 0" />
                <geometry>
                    <mesh filename="package://psm_description/meshes/Si/link_3.stl" />
                </geometry>
            </collision>
        </link>

        <!-- Link 4: -->
        <link name="${prefix}_link_4">
            <inertial>
                <origin xyz="0.041219 -9.0734E-08 0.13651" rpy="0 0 0" />
                <mass value="0.75206" />
                <inertia ixx="0.018546" ixy="3.3933E-09" ixz="0.00048607" iyy="0.018573" iyz="-1.7077E-08" izz="0.00039277" />
            </inertial>
            <visual>
                <origin xyz="0 0 0" rpy="0 0 0" />
                <geometry>
                    <mesh filename="package://psm_description/meshes/Si/link_4.stl" />
                </geometry>
                <material name="Lavender"/>
            </visual>
            <collision>
                <origin xyz="0 0 0" rpy="0 0 0" />
                <geometry>
                    <mesh filename="package://psm_description/meshes/Si/link_4.stl" />
                </geometry>
            </collision>
        </link>

        <!-- Link 5: -->
        <link name="${prefix}_tool_parent" />

        <!-- Link 6: RCM Link -->
        <link name="${prefix}_RCM" />

        <!-- Joint 0: Fixed Joint: Macro Parent Link to Link 0 -->
        <joint name="${prefix}_fixed" type="fixed">
            <parent link="${parent_link}" />
            <child link="${prefix}_link_0" />
            <origin rpy="${rpy}" xyz="${xyz}" />
        </joint>

        <!-- Joint 1: Yaw Joint: Link 0 to Link 1 -->
        <joint name="${prefix}_yaw" type="revolute">
            <origin xyz="0.158 0 0" rpy="0.0 0.0 0.0" />
            <parent link="${prefix}_link_0" />
            <child link="${prefix}_link_1" />
            <axis xyz="-1.0 0.0 0.0" />
            <limit lower="-${PI}" upper="${PI}" effort="0.0" velocity="0.0" />
        </joint>

        <!-- Joint 2: Pitch Joint: Link 1 to Link 2 -->
        <joint name="${prefix}_pitch" type="revolute">
            <origin xyz="0.2987 0 -0.071222" rpy="0 -1.1345 -${PI}" />
            <parent link="${prefix}_link_1" />
            <child link="${prefix}_link_2" />
            <axis xyz="0 -1 0" />
            <limit lower="-${PI}" upper="${PI}" effort="0" velocity="0" />
        </joint>

        <!-- Joint 3: Pitch Joint: Link 2 to Link 3 -->
        <joint name="${prefix}_pitch_2" type="revolute">
            <origin xyz="0.2032 0 0" rpy="0 -0.90761 -${PI}" />
            <parent link="${prefix}_link_2" />
            <child link="${prefix}_link_3" />
            <axis xyz="0 1 0" />
            <limit lower="-${PI}" upper="${PI}" effort="0" velocity="0" />
            <mimic joint="${prefix}_pitch" multiplier="-1" />
        </joint>

        <!-- Joint 4: Pitch Joint: Link 3 to Link 4 -->
        <joint name="${prefix}_pitch_3" type="revolute">
            <origin xyz="0.35966 0 0.16013" rpy="0 -0.063963 0" />
            <parent link="${prefix}_link_3" />
            <child link="${prefix}_link_4" />
            <axis xyz="0 1 0" />
            <limit lower="-${PI}" upper="${PI}" effort="0" velocity="0" />
            <mimic joint="${prefix}_pitch" multiplier="1" />
        </joint>

        <!-- Joint 5: Outer Insertion Reference Joint: Link 4 to Link 5 -->
        <joint name="${prefix}_outer_insertion_ref" type="fixed">
            <origin xyz="0.05061 0 0.41911" rpy="0 0 0" />
            <parent link="${prefix}_link_4" />
            <child link="${prefix}_tool_parent" />
        </joint>

        <!-- Joint 6: RCM Joint: Link 4 to Link 6 -->
        <joint name="${prefix}_jrcm" type="fixed">
            <origin xyz="0.10643 0 -0.1731" rpy="${PI} 0 -${PI/2}" />
            <parent link="${prefix}_link_4" />
            <child link="${prefix}_RCM" />
            <axis xyz="0 0 0" />
        </joint>

    </xacro:macro>

</robot>