<?xml version="1.0" encoding="utf-8"?>
<robot name="dvrk_psm" xmlns:xacro="http://www.ros.org/wiki/xacro">

    <xacro:property name="PI" value="3.1415926535897931" />

    <xacro:macro name="psm_tool_caudier" params="prefix">

        <!-- joint 5: Outer wrist pitch joint -->
        <joint name="outer_wrist_pitch" type="revolute">
            <parent link="${prefix}tool_wrist_shaft_link" />
            <child link="${prefix}tool_wrist_caudier_link" />
            <axis xyz="0 0 1" />
            <origin rpy="-${PI/2} -${PI/2} 0" xyz="0 0 0" />
            <limit lower="-${PI/2}" upper="${PI/2}" velocity=".4" effort="1000" />
        </joint>

        <!-- link 5: tool_wrist_caudier_link -->
        <link name="${prefix}tool_wrist_caudier_link">
            <visual>
                <origin rpy="0.00 -${PI/2} 0.0" xyz="-0.0024 0.00 0.000" />
                <geometry>
                    <mesh filename="package://psm_description/meshes/tool_wrist_caudier_link_1.stl" />
                </geometry>
                <material name="gray">
                    <color rgba="0.5 0.5 0.9 1.0" />
                </material>
            </visual>
            <collision>
                <origin rpy="0.00 -${PI/2} 0.0" xyz="-0.0024 0.00 0.000" />
                <geometry>
                    <mesh filename="package://psm_description/meshes/tool_wrist_caudier_link_1.stl" />
                </geometry>
            </collision>
        </link>

        <!-- joint 6: Tool wrist yaw joint -->
        <joint name="outer_wrist_yaw" type="revolute">
            <parent link="${prefix}tool_wrist_caudier_link" />
            <child link="${prefix}tool_wrist_caudier_link_shaft" />
            <axis xyz="0 0 1" />
            <origin rpy="0.00 -${PI/2} -${PI/2}" xyz="0.0091 0 0" />
            <limit lower="-${PI/2}" upper="${PI/2}" velocity=".4" effort="1000" />
        </joint>

        <!-- link 6: tool_wrist_caudier_link_shaft -->
        <link name="${prefix}tool_wrist_caudier_link_shaft">
            <visual>
                <origin rpy="0.00 ${PI/2} 0.0" xyz="0.0 -0.0002 0.000" />
                <geometry>
                    <mesh
                        filename="package://psm_description/meshes/tool_wrist_caudier_link_1_shaft.stl" />
                </geometry>
                <material name="gray">
                    <color rgba="0.5 0.5 0.9 1.0" />
                </material>
            </visual>
            <collision>
                <origin rpy="0.00 ${PI/2} 0.0" xyz="0.0 0.00 0.000" />
                <geometry>
                    <mesh
                        filename="package://psm_description/meshes/tool_wrist_caudier_link_1_shaft.stl" />
                </geometry>
            </collision>
        </link>

        <!-- joint 7-0: Outer open angle 1  -->
        <joint name="jaw" type="revolute">
            <parent link="${prefix}tool_wrist_caudier_link_shaft" />
            <child link="${prefix}tool_wrist_caudier_ee_link_0" />
            <axis xyz="0 0 1" />
            <origin rpy="0 0 0" xyz="0 0 0" />
            <limit lower="0" upper="${PI/2}" velocity=".4" effort="1000" />
        </joint>

        <!-- link 7-0: Outer open angle virtual -->
        <link name="${prefix}tool_wrist_caudier_ee_link_0">
            <visual>
                <origin rpy="0 0 0" xyz="0 0 0" />
                <geometry>
                    <box size="0 0 0" />
                </geometry>
            </visual>
        </link>

        <!-- joint 7-1: Outer open angle 1 -->
        <joint name="jaw_mimic_1" type="revolute">
            <parent link="${prefix}tool_wrist_caudier_link_shaft" />
            <child link="${prefix}tool_wrist_caudier_link_2_left" />
            <axis xyz="0 0 1" />
            <origin rpy="0 0 0" xyz="0 0 0" />
            <limit lower="0" upper="${PI/2}" velocity=".4" effort="1000" />
            <mimic joint="jaw" multiplier="0.5" />
        </joint>

        <!-- link 7-1: Outer open angle link 1 -->
        <link name="${prefix}tool_wrist_caudier_link_2_left">
            <visual>
                <origin rpy="0.0 0 0.0" xyz="0 0 0.00195" />
                <geometry>
                    <mesh filename="package://psm_description/meshes/tool_wrist_caudier_link_2.stl" />
                </geometry>
            </visual>
        </link>

        <!-- joint 7-2: Outer open angle 2  -->
        <joint name="jaw_mimic_2" type="revolute">
            <parent link="${prefix}tool_wrist_caudier_link_shaft" />
            <child link="${prefix}tool_wrist_caudier_link_2_right" />
            <axis xyz="0 0 1" />
            <origin rpy="${PI} 0 0" xyz="0 0 0" />
            <limit lower="0" upper="${PI/2}" velocity=".4" effort="1000" />
            <mimic joint="jaw" multiplier="0.5" />
        </joint>

        <!-- link 7-2: Outer open angle link 2 -->
        <link name="${prefix}tool_wrist_caudier_link_2_right">
            <visual>
                <origin rpy="0 0 -${PI}" xyz="0 0 0.00195" />
                <geometry>
                    <mesh filename="package://psm_description/meshes/tool_wrist_caudier_link_2.stl" />
                </geometry>
            </visual>
        </link>

        <!-- tool tip   -->
        <joint name="tool_wrist_caudier_ee" type="fixed">
            <parent link="${prefix}tool_wrist_caudier_link_shaft" />
            <child link="${prefix}tool_wrist_caudier_ee_link" />
            <origin rpy="0.0 ${PI/2} ${PI/2}" xyz="0 0 0" />
        </joint>

        <!-- link 6-3:  -->
        <link name="${prefix}tool_wrist_caudier_ee_link" />

    </xacro:macro>

</robot>